Workbook

Sheet Pivot
A3: Bline | B3: salesrep_code | C3: salesrep_name | D3: cust_code | E3: cust_name | F3: cont_code | G3: cont_name | H3: title_name | I3: ques_name | J3: sub_ques_name | K3: criteria_name | L3: expec
A4: ALLIANCE 1 | B4: 20001294 | C4: Nguyen Ngoc Diem | D4: 121035712 | E4: TRUNG TAM Y TE KHU VUC PHU GIAO | F4: VN00039762 | G4: BUI THUAN | H4: HCP Data Profiling Questionnaire | I4: Profiling Questionnaire | J4: 1. Trong 6 tháng vừa qua, BS đã được tiếp cận hoặc nhận thông tin từ công ty qua những hình thức/ kênh nào? | K4: Gặp mặt trực tiếp/ Hội nghị đào tạo y khoa trực tiếp | L4: (blank)
J5: 2. Vui lòng đánh giá từng kênh theo thang điểm từ 0 đến 10, cho hình thức Email/ Mạng xã hội/ Tin nhắn | K5: 5 | L5: (blank)
J6: 2. Vui lòng đánh giá từng kênh theo thang điểm từ 0 đến 10, cho hình thức Gặp mặt trực tiếp/ Hội thảo đào tạo y khoa trực tiếp | K6: 8 | L6: (blank)
J7: 2. Vui lòng đánh giá từng kênh theo thang điểm từ 0 đến 10, cho hình thức Video call/ Hội thảo trực tuyến | K7: 5 | L7: (blank)
I8: Digital / Personas Questionnaire | J8: 3. Ngoài các hình thức tiếp cận như gặp mặt trực tiếp/ tương tác trực tuyến hay thông qua các mạng xã hội…,còn nguồn thông tin nào khác mà BS thấy hữu ích cho việc cập nhật y khoa (ví dụ: hiệp hội, trang web hội chuyên ngành,...)? | K8: (blank) | L8: zalo
J9: 4. BS thường ưu tiên tương tác với công ty theo hình thức nào? | K9: Ưu tiên tương tác đa kênh | L9: (blank)
J10: 5. Trong các yếu tố sau, yếu tố nào ảnh hưởng nhiều nhất đến quyết định điều trị của bác sĩ? | K10: Trải nghiệm và lợi ích tổng thể cho bệnh nhân (GREEN) | L10: (blank)
D11: 121041955 | E11: CONG TY CO PHAN BENH VIEN MY PHUOC | F11: VN00057430 | G11: PHAM MINH HOANG | H11: HCP Data Profiling Questionnaire | I11: Profiling Questionnaire | J11: 1. Trong 6 tháng vừa qua, BS đã được tiếp cận hoặc nhận thông tin từ công ty qua những hình thức/ kênh nào? | K11: Email/ Mạng xã hội/ Tin nhắn | L11: (blank)
K12: Gặp mặt trực tiếp/ Hội nghị đào tạo y khoa trực tiếp | L12: (blank)
K13: Hội thảo trực tuyến/ Gọi Video | L13: (blank)
J14: 2. Vui lòng đánh giá từng kênh theo thang điểm từ 0 đến 10, cho hình thức Email/ Mạng xã hội/ Tin nhắn | K14: 5 | L14: (blank)
J15: 2. Vui lòng đánh giá từng kênh theo thang điểm từ 0 đến 10, cho hình thức Gặp mặt trực tiếp/ Hội thảo đào tạo y khoa trực tiếp | K15: 6 | L15: (blank)
K16: 8 | L16: (blank)
J17: 2. Vui lòng đánh giá từng kênh theo thang điểm từ 0 đến 10, cho hình thức Video call/ Hội thảo trực tuyến | K17: 5 | L17: (blank)
I18: Digital / Personas Questionnaire | J18: 3. Ngoài các hình thức tiếp cận như gặp mặt trực tiếp/ tương tác trực tuyến hay thông qua các mạng xã hội…,còn nguồn thông tin nào khác mà BS thấy hữu ích cho việc cập nhật y khoa (ví dụ: hiệp hội, trang web hội chuyên ngành,...)? | K18: (blank) | L18: web
J19: 4. BS thường ưu tiên tương tác với công ty theo hình thức nào? | K19: Ưu tiên tương tác đa kênh | L19: (blank)
K20: Ưu tiên tương tác trực tiếp | L20: (blank)
J21: 5. Trong các yếu tố sau, yếu tố nào ảnh hưởng nhiều nhất đến quyết định điều trị của bác sĩ? | K21: Kết quả điều trị thực tế (RED) | L21: (blank)
D22: 121050614 | E22: CONG TY TNHH BENH VIENDA KHOA HOAN HAO | F22: VN00046922 | G22: NGUYEN THI THU THAO | H22: HCP Data Profiling Questionnaire | I22: Profiling Questionnaire | J22: 1. Trong 6 tháng vừa qua, BS đã được tiếp cận hoặc nhận thông tin từ công ty qua những hình thức/ kênh nào? | K22: Email/ Mạng xã hội/ Tin nhắn | L22: (blank)
K23: Gặp mặt trực tiếp/ Hội nghị đào tạo y khoa trực tiếp | L23: (blank)
K24: Hội thảo trực tuyến/ Gọi Video | L24: (blank)
J25: 2. Vui lòng đánh giá từng kênh theo thang điểm từ 0 đến 10, cho hình thức Email/ Mạng xã hội/ Tin nhắn | K25: 6 | L25: (blank)
J26: 2. Vui lòng đánh giá từng kênh theo thang điểm từ 0 đến 10, cho hình thức Gặp mặt trực tiếp/ Hội thảo đào tạo y khoa trực tiếp | K26: 8 | L26: (blank)
J27: 2. Vui lòng đánh giá từng kênh theo thang điểm từ 0 đến 10, cho hình thức Video call/ Hội thảo trực tuyến | K27: 6 | L27: (blank)
I28: Digital / Personas Questionnaire | J28: 3. Ngoài các hình thức tiếp cận như gặp mặt trực tiếp/ tương tác trực tuyến hay thông qua các mạng xã hội…,còn nguồn thông tin nào khác mà BS thấy hữu ích cho việc cập nhật y khoa (ví dụ: hiệp hội, trang web hội chuyên ngành,...)? | K28: (blank) | L28: internet
J29: 4. BS thường ưu tiên tương tác với công ty theo hình thức nào? | K29: Kết hợp trực tiếp và kỹ thuật số | L29: (blank)
J30: 5. Trong các yếu tố sau, yếu tố nào ảnh hưởng nhiều nhất đến quyết định điều trị của bác sĩ? | K30: Trải nghiệm và lợi ích tổng thể cho bệnh nhân (GREEN) | L30: (blank)
F31: VN00063625 | G31: NGUYEN XUAN TUYEN | H31: HCP Data Profiling Questionnaire | I31: Profiling Questionnaire | J31: 1. Trong 6 tháng vừa qua, BS đã được tiếp cận hoặc nhận thông tin từ công ty qua những hình thức/ kênh nào? | K31: Email/ Mạng xã hội/ Tin nhắn | L31: (blank)
K32: Gặp mặt trực tiếp/ Hội nghị đào tạo y khoa trực tiếp | L32: (blank)
K33: Hội thảo trực tuyến/ Gọi Video | L33: (blank)
J34: 2. Vui lòng đánh giá từng kênh theo thang điểm từ 0 đến 10, cho hình thức Email/ Mạng xã hội/ Tin nhắn | K34: 5 | L34: (blank)
J35: 2. Vui lòng đánh giá từng kênh theo thang điểm từ 0 đến 10, cho hình thức Gặp mặt trực tiếp/ Hội thảo đào tạo y khoa trực tiếp | K35: 6 | L35: (blank)
J36: 2. Vui lòng đánh giá từng kênh theo thang điểm từ 0 đến 10, cho hình thức Video call/ Hội thảo trực tuyến | K36: 5 | L36: (blank)
I37: Digital / Personas Questionnaire | J37: 3. Ngoài các hình thức tiếp cận như gặp mặt trực tiếp/ tương tác trực tuyến hay thông qua các mạng xã hội…,còn nguồn thông tin nào khác mà BS thấy hữu ích cho việc cập nhật y khoa (ví dụ: hiệp hội, trang web hội chuyên ngành,...)? | K37: (blank) | L37: cac trang mạng
J38: 4. BS thường ưu tiên tương tác với công ty theo hình thức nào? | K38: Ưu tiên tương tác đa kênh | L38: (blank)
J39: 5. Trong các yếu tố sau, yếu tố nào ảnh hưởng nhiều nhất đến quyết định điều trị của bác sĩ? | K39: Kết quả điều trị thực tế (RED) | L39: (blank)
F40: VN00063626 | G40: NGUYEN THI THUY TRANG | H40: HCP Data Profiling Questionnaire | I40: Profiling Questionnaire | J40: 1. Trong 6 tháng vừa qua, BS đã được tiếp cận hoặc nhận thông tin từ công ty qua những hình thức/ kênh nào? | K40: Email/ Mạng xã hội/ Tin nhắn | L40: (blank)
K41: Gặp mặt trực tiếp/ Hội nghị đào tạo y khoa trực tiếp | L41: (blank)
K42: Hội thảo trực tuyến/ Gọi Video | L42: (blank)
...

Sheet Market_Survey
A1: Bline | B1: txn_no | C1: txn_status | D1: salesrep_code | E1: salesrep_name | F1: visit_id | G1: txn_date | H1: cust_code | I1: cust_name | J1: cont_code | K1: cont_name | L1: title_code | M1: title_name | N1: ques_code | O1: ques_name | P1: ques_desc | Q1: sub_ques_code | R1: sub_ques_name | S1: criteria_code | T1: criteria_name | U1: expec | V1: date_val | W1: opt_val | X1: gen_comment | Y1: cancel_reason | Z1: reason_code | AA1: reason_name | AB1: txn_timestamp
A2: ALLIANCE 1 | B2: VN20001294MSS000001 | C2: P | D2: 20001294 | E2: Nguyen Ngoc Diem | F2: 2026032300034777 | G2: 46104 | H2: 121041955 | I2: CONG TY CO PHAN BENH VIEN MY PHUOC | J2: VN00057430 | K2: PHAM MINH HOANG | L2: OB_MSS_02 | M2: HCP Data Profiling Questionnaire | N2: Part_1 | O2: Profiling Questionnaire | Q2: S1 | R2: 1. Trong 6 tháng vừa qua, BS đã được tiếp cận hoặc nhận thông tin từ công ty qua những hình thức/ kênh nào? | S2: S1_01 | T2: Gặp mặt trực tiếp/ Hội nghị đào tạo y khoa trực tiếp | V2: 2 | AB2: 46104.572
A3: ALLIANCE 1 | B3: VN20001294MSS000001 | C3: P | D3: 20001294 | E3: Nguyen Ngoc Diem | F3: 2026032300034777 | G3: 46104 | H3: 121041955 | I3: CONG TY CO PHAN BENH VIEN MY PHUOC | J3: VN00057430 | K3: PHAM MINH HOANG | L3: OB_MSS_02 | M3: HCP Data Profiling Questionnaire | N3: Part_1 | O3: Profiling Questionnaire | Q3: S2 | R3: 2. Vui lòng đánh giá từng kênh theo thang điểm từ 0 đến 10, cho hình thức Gặp mặt trực tiếp/ Hội thảo đào tạo y khoa trực tiếp | S3: S2_06 | T3: 6 | V3: 2 | AB3: 46104.572
A4: ALLIANCE 1 | B4: VN20001294MSS000001 | C4: P | D4: 20001294 | E4: Nguyen Ngoc Diem | F4: 2026032300034777 | G4: 46104 | H4: 121041955 | I4: CONG TY CO PHAN BENH VIEN MY PHUOC | J4: VN00057430 | K4: PHAM MINH HOANG | L4: OB_MSS_02 | M4: HCP Data Profiling Questionnaire | N4: Part_1 | O4: Profiling Questionnaire | Q4: S3 | R4: 2. Vui lòng đánh giá từng kênh theo thang điểm từ 0 đến 10, cho hình thức Email/ Mạng xã hội/ Tin nhắn | S4: S3_05 | T4: 5 | V4: 2 | AB4: 46104.572
A5: ALLIANCE 1 | B5: VN20001294MSS000001 | C5: P | D5: 20001294 | E5: Nguyen Ngoc Diem | F5: 2026032300034777 | G5: 46104 | H5: 121041955 | I5: CONG TY CO PHAN BENH VIEN MY PHUOC | J5: VN00057430 | K5: PHAM MINH HOANG | L5: OB_MSS_02 | M5: HCP Data Profiling Questionnaire | N5: Part_1 | O5: Profiling Questionnaire | Q5: S4 | R5: 2. Vui lòng đánh giá từng kênh theo thang điểm từ 0 đến 10, cho hình thức Video call/ Hội thảo trực tuyến | S5: S4_05 | T5: 5 | V5: 2 | AB5: 46104.572
A6: ALLIANCE 1 | B6: VN20001294MSS000001 | C6: P | D6: 20001294 | E6: Nguyen Ngoc Diem | F6: 2026032300034777 | G6: 46104 | H6: 121041955 | I6: CONG TY CO PHAN BENH VIEN MY PHUOC | J6: VN00057430 | K6: PHAM MINH HOANG | L6: OB_MSS_02 | M6: HCP Data Profiling Questionnaire | N6: Part_2 | O6: Digital / Personas Questionnaire | Q6: S1 | R6: 3. Ngoài các hình thức tiếp cận như gặp mặt trực tiếp/ tương tác trực tuyến hay thông qua các mạng xã hội…,còn nguồn thông tin nào khác mà BS thấy hữu ích cho việc cập nhật y khoa (ví dụ: hiệp hội, trang web hội chuyên ngành,...)? | U6: web | V6: 2 | AB6: 46104.572
A7: ALLIANCE 1 | B7: VN20001294MSS000001 | C7: P | D7: 20001294 | E7: Nguyen Ngoc Diem | F7: 2026032300034777 | G7: 46104 | H7: 121041955 | I7: CONG TY CO PHAN BENH VIEN MY PHUOC | J7: VN00057430 | K7: PHAM MINH HOANG | L7: OB_MSS_02 | M7: HCP Data Profiling Questionnaire | N7: Part_2 | O7: Digital / Personas Questionnaire | Q7: S2 | R7: 4. BS thường ưu tiên tương tác với công ty theo hình thức nào? | S7: S2_03 | T7: Ưu tiên tương tác đa kênh | V7: 2 | AB7: 46104.572
A8: ALLIANCE 1 | B8: VN20001294MSS000001 | C8: P | D8: 20001294 | E8: Nguyen Ngoc Diem | F8: 2026032300034777 | G8: 46104 | H8: 121041955 | I8: CONG TY CO PHAN BENH VIEN MY PHUOC | J8: VN00057430 | K8: PHAM MINH HOANG | L8: OB_MSS_02 | M8: HCP Data Profiling Questionnaire | N8: Part_2 | O8: Digital / Personas Questionnaire | Q8: S3 | R8: 5. Trong các yếu tố sau, yếu tố nào ảnh hưởng nhiều nhất đến quyết định điều trị của bác sĩ? | S8: S3_01 | T8: Kết quả điều trị thực tế (RED) | V8: 2 | AB8: 46104.572
A9: ALLIANCE 1 | B9: VN20001294MSS000002 | C9: P | D9: 20001294 | E9: Nguyen Ngoc Diem | F9: 2026032300034778 | G9: 46104 | H9: 121087942 | I9: CONG TY CO PHAN THUONG MAI DICHVU Y TE NHAN NGHIA | J9: VN00063623 | K9: TRAN THANH AN | L9: OB_MSS_02 | M9: HCP Data Profiling Questionnaire | N9: Part_1 | O9: Profiling Questionnaire | Q9: S1 | R9: 1. Trong 6 tháng vừa qua, BS đã được tiếp cận hoặc nhận thông tin từ công ty qua những hình thức/ kênh nào? | S9: S1_01 | T9: Gặp mặt trực tiếp/ Hội nghị đào tạo y khoa trực tiếp | V9: 2 | AB9: 46104.572
A10: ALLIANCE 1 | B10: VN20001294MSS000002 | C10: P | D10: 20001294 | E10: Nguyen Ngoc Diem | F10: 2026032300034778 | G10: 46104 | H10: 121087942 | I10: CONG TY CO PHAN THUONG MAI DICHVU Y TE NHAN NGHIA | J10: VN00063623 | K10: TRAN THANH AN | L10: OB_MSS_02 | M10: HCP Data Profiling Questionnaire | N10: Part_1 | O10: Profiling Questionnaire | Q10: S2 | R10: 2. Vui lòng đánh giá từng kênh theo thang điểm từ 0 đến 10, cho hình thức Gặp mặt trực tiếp/ Hội thảo đào tạo y khoa trực tiếp | S10: S2_07 | T10: 7 | V10: 2 | AB10: 46104.572
A11: ALLIANCE 1 | B11: VN20001294MSS000002 | C11: P | D11: 20001294 | E11: Nguyen Ngoc Diem | F11: 2026032300034778 | G11: 46104 | H11: 121087942 | I11: CONG TY CO PHAN THUONG MAI DICHVU Y TE NHAN NGHIA | J11: VN00063623 | K11: TRAN THANH AN | L11: OB_MSS_02 | M11: HCP Data Profiling Questionnaire | N11: Part_1 | O11: Profiling Questionnaire | Q11: S3 | R11: 2. Vui lòng đánh giá từng kênh theo thang điểm từ 0 đến 10, cho hình thức Email/ Mạng xã hội/ Tin nhắn | S11: S3_05 | T11: 5 | V11: 2 | AB11: 46104.572
A12: ALLIANCE 1 | B12: VN20001294MSS000002 | C12: P | D12: 20001294 | E12: Nguyen Ngoc Diem | F12: 2026032300034778 | G12: 46104 | H12: 121087942 | I12: CONG TY CO PHAN THUONG MAI DICHVU Y TE NHAN NGHIA | J12: VN00063623 | K12: TRAN THANH AN | L12: OB_MSS_02 | M12: HCP Data Profiling Questionnaire | N12: Part_1 | O12: Profiling Questionnaire | Q12: S4 | R12: 2. Vui lòng đánh giá từng kênh theo thang điểm từ 0 đến 10, cho hình thức Video call/ Hội thảo trực tuyến | S12: S4_05 | T12: 5 | V12: 2 | AB12: 46104.572
A13: ALLIANCE 1 | B13: VN20001294MSS000002 | C13: P | D13: 20001294 | E13: Nguyen Ngoc Diem | F13: 2026032300034778 | G13: 46104 | H13: 121087942 | I13: CONG TY CO PHAN THUONG MAI DICHVU Y TE NHAN NGHIA | J13: VN00063623 | K13: TRAN THANH AN | L13: OB_MSS_02 | M13: HCP Data Profiling Questionnaire | N13: Part_2 | O13: Digital / Personas Questionnaire | Q13: S1 | R13: 3. Ngoài các hình thức tiếp cận như gặp mặt trực tiếp/ tương tác trực tuyến hay thông qua các mạng xã hội…,còn nguồn thông tin nào khác mà BS thấy hữu ích cho việc cập nhật y khoa (ví dụ: hiệp hội, trang web hội chuyên ngành,...)? | U13: hoi nghi | V13: 2 | AB13: 46104.572
A14: ALLIANCE 1 | B14: VN20001294MSS000002 | C14: P | D14: 20001294 | E14: Nguyen Ngoc Diem | F14: 2026032300034778 | G14: 46104 | H14: 121087942 | I14: CONG TY CO PHAN THUONG MAI DICHVU Y TE NHAN NGHIA | J14: VN00063623 | K14: TRAN THANH AN | L14: OB_MSS_02 | M14: HCP Data Profiling Questionnaire | N14: Part_2 | O14: Digital / Personas Questionnaire | Q14: S2 | R14: 4. BS thường ưu tiên tương tác với công ty theo hình thức nào? | S14: S2_01 | T14: Ưu tiên tương tác trực tiếp | V14: 2 | AB14: 46104.572
A15: ALLIANCE 1 | B15: VN20001294MSS000002 | C15: P | D15: 20001294 | E15: Nguyen Ngoc Diem | F15: 2026032300034778 | G15: 46104 | H15: 121087942 | I15: CONG TY CO PHAN THUONG MAI DICHVU Y TE NHAN NGHIA | J15: VN00063623 | K15: TRAN THANH AN | L15: OB_MSS_02 | M15: HCP Data Profiling Questionnaire | N15: Part_2 | O15: Digital / Personas Questionnaire | Q15: S3 | R15: 5. Trong các yếu tố sau, yếu tố nào ảnh hưởng nhiều nhất đến quyết định điều trị của bác sĩ? | S15: S3_02 | T15: Dựa trên dữ liệu, bằng chứng khoa học (BLUE) | V15: 2 | AB15: 46104.572
A16: ALLIANCE 1 | B16: VN20001294MSS000003 | C16: P | D16: 20001294 | E16: Nguyen Ngoc Diem | F16: 2026032300034779 | G16: 46104 | H16: 121035712 | I16: TRUNG TAM Y TE KHU VUC PHU GIAO | J16: VN00039762 | K16: BUI THUAN | L16: OB_MSS_02 | M16: HCP Data Profiling Questionnaire | N16: Part_1 | O16: Profiling Questionnaire | Q16: S1 | R16: 1. Trong 6 tháng vừa qua, BS đã được tiếp cận hoặc nhận thông tin từ công ty qua những hình thức/ kênh nào? | S16: S1_01 | T16: Gặp mặt trực tiếp/ Hội nghị đào tạo y khoa trực tiếp | V16: 2 | AB16: 46104.691
A17: ALLIANCE 1 | B17: VN20001294MSS000003 | C17: P | D17: 20001294 | E17: Nguyen Ngoc Diem | F17: 2026032300034779 | G17: 46104 | H17: 121035712 | I17: TRUNG TAM Y TE KHU VUC PHU GIAO | J17: VN00039762 | K17: BUI THUAN | L17: OB_MSS_02 | M17: HCP Data Profiling Questionnaire | N17: Part_1 | O17: Profiling Questionnaire | Q17: S2 | R17: 2. Vui lòng đánh giá từng kênh theo thang điểm từ 0 đến 10, cho hình thức Gặp mặt trực tiếp/ Hội thảo đào tạo y khoa trực tiếp | S17: S2_08 | T17: 8 | V17: 2 | AB17: 46104.691
A18: ALLIANCE 1 | B18: VN20001294MSS000003 | C18: P | D18: 20001294 | E18: Nguyen Ngoc Diem | F18: 2026032300034779 | G18: 46104 | H18: 121035712 | I18: TRUNG TAM Y TE KHU VUC PHU GIAO | J18: VN00039762 | K18: BUI THUAN | L18: OB_MSS_02 | M18: HCP Data Profiling Questionnaire | N18: Part_1 | O18: Profiling Questionnaire | Q18: S3 | R18: 2. Vui lòng đánh giá từng kênh theo thang điểm từ 0 đến 10, cho hình thức Email/ Mạng xã hội/ Tin nhắn | S18: S3_05 | T18: 5 | V18: 2 | AB18: 46104.691
A19: ALLIANCE 1 | B19: VN20001294MSS000003 | C19: P | D19: 20001294 | E19: Nguyen Ngoc Diem | F19: 2026032300034779 | G19: 46104 | H19: 121035712 | I19: TRUNG TAM Y TE KHU VUC PHU GIAO | J19: VN00039762 | K19: BUI THUAN | L19: OB_MSS_02 | M19: HCP Data Profiling Questionnaire | N19: Part_1 | O19: Profiling Questionnaire | Q19: S4 | R19: 2. Vui lòng đánh giá từng kênh theo thang điểm từ 0 đến 10, cho hình thức Video call/ Hội thảo trực tuyến | S19: S4_05 | T19: 5 | V19: 2 | AB19: 46104.691
A20: ALLIANCE 1 | B20: VN20001294MSS000003 | C20: P | D20: 20001294 | E20: Nguyen Ngoc Diem | F20: 2026032300034779 | G20: 46104 | H20: 121035712 | I20: TRUNG TAM Y TE KHU VUC PHU GIAO | J20: VN00039762 | K20: BUI THUAN | L20: OB_MSS_02 | M20: HCP Data Profiling Questionnaire | N20: Part_2 | O20: Digital / Personas Questionnaire | Q20: S1 | R20: 3. Ngoài các hình thức tiếp cận như gặp mặt trực tiếp/ tương tác trực tuyến hay thông qua các mạng xã hội…,còn nguồn thông tin nào khác mà BS thấy hữu ích cho việc cập nhật y khoa (ví dụ: hiệp hội, trang web hội chuyên ngành,...)? | U20: zalo | V20: 2 | AB20: 46104.691
A21: ALLIANCE 1 | B21: VN20001294MSS000003 | C21: P | D21: 20001294 | E21: Nguyen Ngoc Diem | F21: 2026032300034779 | G21: 46104 | H21: 121035712 | I21: TRUNG TAM Y TE KHU VUC PHU GIAO | J21: VN00039762 | K21: BUI THUAN | L21: OB_MSS_02 | M21: HCP Data Profiling Questionnaire | N21: Part_2 | O21: Digital / Personas Questionnaire | Q21: S2 | R21: 4. BS thường ưu tiên tương tác với công ty theo hình thức nào? | S21: S2_03 | T21: Ưu tiên tương tác đa kênh | V21: 2 | AB21: 46104.691
A22: ALLIANCE 1 | B22: VN20001294MSS000003 | C22: P | D22: 20001294 | E22: Nguyen Ngoc Diem | F22: 2026032300034779 | G22: 46104 | H22: 121035712 | I22: TRUNG TAM Y TE KHU VUC PHU GIAO | J22: VN00039762 | K22: BUI THUAN | L22: OB_MSS_02 | M22: HCP Data Profiling Questionnaire | N22: Part_2 | O22: Digital / Personas Questionnaire | Q22: S3 | R22: 5. Trong các yếu tố sau, yếu tố nào ảnh hưởng nhiều nhất đến quyết định điều trị của bác sĩ? | S22: S3_03 | T22: Trải nghiệm và lợi ích tổng thể cho bệnh nhân (GREEN) | V22: 2 | AB22: 46104.691
A23: ALLIANCE 1 | B23: VN20001294MSS000004 | C23: P | D23: 20001294 | E23: Nguyen Ngoc Diem | F23: 2026032300034781 | G23: 46104 | H23: 121050614 | I23: CONG TY TNHH BENH VIENDA KHOA HOAN HAO | J23: VN00063625 | K23: NGUYEN XUAN TUYEN | L23: OB_MSS_02 | M23: HCP Data Profiling Questionnaire | N23: Part_1 | O23: Profiling Questionnaire | Q23: S1 | R23: 1. Trong 6 tháng vừa qua, BS đã được tiếp cận hoặc nhận thông tin từ công ty qua những hình thức/ kênh nào? | S23: S1_01 | T23: Gặp mặt trực tiếp/ Hội nghị đào tạo y khoa trực tiếp | V23: 2 | AB23: 46104.708
A24: ALLIANCE 1 | B24: VN20001294MSS000004 | C24: P | D24: 20001294 | E24: Nguyen Ngoc Diem | F24: 2026032300034781 | G24: 46104 | H24: 121050614 | I24: CONG TY TNHH BENH VIENDA KHOA HOAN HAO | J24: VN00063625 | K24: NGUYEN XUAN TUYEN | L24: OB_MSS_02 | M24: HCP Data Profiling Questionnaire | N24: Part_1 | O24: Profiling Questionnaire | Q24: S1 | R24: 1. Trong 6 tháng vừa qua, BS đã được tiếp cận hoặc nhận thông tin từ công ty qua những hình thức/ kênh nào? | S24: S1_02 | T24: Email/ Mạng xã hội/ Tin nhắn | V24: 2 | AB24: 46104.708
A25: ALLIANCE 1 | B25: VN20001294MSS000004 | C25: P | D25: 20001294 | E25: Nguyen Ngoc Diem | F25: 2026032300034781 | G25: 46104 | H25: 121050614 | I25: CONG TY TNHH BENH VIENDA KHOA HOAN HAO | J25: VN00063625 | K25: NGUYEN XUAN TUYEN | L25: OB_MSS_02 | M25: HCP Data Profiling Questionnaire | N25: Part_1 | O25: Profiling Questionnaire | Q25: S1 | R25: 1. Trong 6 tháng vừa qua, BS đã được tiếp cận hoặc nhận thông tin từ công ty qua những hình thức/ kênh nào? | S25: S1_03 | T25: Hội thảo trực tuyến/ Gọi Video | V25: 2 | AB25: 46104.708
A26: ALLIANCE 1 | B26: VN20001294MSS000004 | C26: P | D26: 20001294 | E26: Nguyen Ngoc Diem | F26: 2026032300034781 | G26: 46104 | H26: 121050614 | I26: CONG TY TNHH BENH VIENDA KHOA HOAN HAO | J26: VN00063625 | K26: NGUYEN XUAN TUYEN | L26: OB_MSS_02 | M26: HCP Data Profiling Questionnaire | N26: Part_1 | O26: Profiling Questionnaire | Q26: S2 | R26: 2. Vui lòng đánh giá từng kênh theo thang điểm từ 0 đến 10, cho hình thức Gặp mặt trực tiếp/ Hội thảo đào tạo y khoa trực tiếp | S26: S2_06 | T26: 6 | V26: 2 | AB26: 46104.708
A27: ALLIANCE 1 | B27: VN20001294MSS000004 | C27: P | D27: 20001294 | E27: Nguyen Ngoc Diem | F27: 2026032300034781 | G27: 46104 | H27: 121050614 | I27: CONG TY TNHH BENH VIENDA KHOA HOAN HAO | J27: VN00063625 | K27: NGUYEN XUAN TUYEN | L27: OB_MSS_02 | M27: HCP Data Profiling Questionnaire | N27: Part_1 | O27: Profiling Questionnaire | Q27: S3 | R27: 2. Vui lòng đánh giá từng kênh theo thang điểm từ 0 đến 10, cho hình thức Email/ Mạng xã hội/ Tin nhắn | S27: S3_05 | T27: 5 | V27: 2 | AB27: 46104.708
A28: ALLIANCE 1 | B28: VN20001294MSS000004 | C28: P | D28: 20001294 | E28: Nguyen Ngoc Diem | F28: 2026032300034781 | G28: 46104 | H28: 121050614 | I28: CONG TY TNHH BENH VIENDA KHOA HOAN HAO | J28: VN00063625 | K28: NGUYEN XUAN TUYEN | L28: OB_MSS_02 | M28: HCP Data Profiling Questionnaire | N28: Part_1 | O28: Profiling Questionnaire | Q28: S4 | R28: 2. Vui lòng đánh giá từng kênh theo thang điểm từ 0 đến 10, cho hình thức Video call/ Hội thảo trực tuyến | S28: S4_05 | T28: 5 | V28: 2 | AB28: 46104.708
A29: ALLIANCE 1 | B29: VN20001294MSS000004 | C29: P | D29: 20001294 | E29: Nguyen Ngoc Diem | F29: 2026032300034781 | G29: 46104 | H29: 121050614 | I29: CONG TY TNHH BENH VIENDA KHOA HOAN HAO | J29: VN00063625 | K29: NGUYEN XUAN TUYEN | L29: OB_MSS_02 | M29: HCP Data Profiling Questionnaire | N29: Part_2 | O29: Digital / Personas Questionnaire | Q29: S1 | R29: 3. Ngoài các hình thức tiếp cận như gặp mặt trực tiếp/ tương tác trực tuyến hay thông qua các mạng xã hội…,còn nguồn thông tin nào khác mà BS thấy hữu ích cho việc cập nhật y khoa (ví dụ: hiệp hội, trang web hội chuyên ngành,...)? | U29: cac trang mạng | V29: 2 | AB29: 46104.708
A30: ALLIANCE 1 | B30: VN20001294MSS000004 | C30: P | D30: 20001294 | E30: Nguyen Ngoc Diem | F30: 2026032300034781 | G30: 46104 | H30: 121050614 | I30: CONG TY TNHH BENH VIENDA KHOA HOAN HAO | J30: VN00063625 | K30: NGUYEN XUAN TUYEN | L30: OB_MSS_02 | M30: HCP Data Profiling Questionnaire | N30: Part_2 | O30: Digital / Personas Questionnaire | Q30: S2 | R30: 4. BS thường ưu tiên tương tác với công ty theo hình thức nào? | S30: S2_03 | T30: Ưu tiên tương tác đa kênh | V30: 2 | AB30: 46104.708
A31: ALLIANCE 1 | B31: VN20001294MSS000004 | C31: P | D31: 20001294 | E31: Nguyen Ngoc Diem | F31: 2026032300034781 | G31: 46104 | H31: 121050614 | I31: CONG TY TNHH BENH VIENDA KHOA HOAN HAO | J31: VN00063625 | K31: NGUYEN XUAN TUYEN | L31: OB_MSS_02 | M31: HCP Data Profiling Questionnaire | N31: Part_2 | O31: Digital / Personas Questionnaire | Q31: S3 | R31: 5. Trong các yếu tố sau, yếu tố nào ảnh hưởng nhiều nhất đến quyết định điều trị của bác sĩ? | S31: S3_01 | T31: Kết quả điều trị thực tế (RED) | V31: 2 | AB31: 46104.708
A32: ALLIANCE 1 | B32: VN20001294MSS000005 | C32: P | D32: 20001294 | E32: Nguyen Ngoc Diem | F32: 2026032300034782 | G32: 46104 | H32: 121050614 | I32: CONG TY TNHH BENH VIENDA KHOA HOAN HAO | J32: VN00063626 | K32: NGUYEN THI THUY TRANG | L32: OB_MSS_02 | M32: HCP Data Profiling Questionnaire | N32: Part_1 | O32: Profiling Questionnaire | Q32: S1 | R32: 1. Trong 6 tháng vừa qua, BS đã được tiếp cận hoặc nhận thông tin từ công ty qua những hình thức/ kênh nào? | S32: S1_01 | T32: Gặp mặt trực tiếp/ Hội nghị đào tạo y khoa trực tiếp | V32: 2 | AB32: 46104.716
A33: ALLIANCE 1 | B33: VN20001294MSS000005 | C33: P | D33: 20001294 | E33: Nguyen Ngoc Diem | F33: 2026032300034782 | G33: 46104 | H33: 121050614 | I33: CONG TY TNHH BENH VIENDA KHOA HOAN HAO | J33: VN00063626 | K33: NGUYEN THI THUY TRANG | L33: OB_MSS_02 | M33: HCP Data Profiling Questionnaire | N33: Part_1 | O33: Profiling Questionnaire | Q33: S1 | R33: 1. Trong 6 tháng vừa qua, BS đã được tiếp cận hoặc nhận thông tin từ công ty qua những hình thức/ kênh nào? | S33: S1_02 | T33: Email/ Mạng xã hội/ Tin nhắn | V33: 2 | AB33: 46104.716
A34: ALLIANCE 1 | B34: VN20001294MSS000005 | C34: P | D34: 20001294 | E34: Nguyen Ngoc Diem | F34: 2026032300034782 | G34: 46104 | H34: 121050614 | I34: CONG TY TNHH BENH VIENDA KHOA HOAN HAO | J34: VN00063626 | K34: NGUYEN THI THUY TRANG | L34: OB_MSS_02 | M34: HCP Data Profiling Questionnaire | N34: Part_1 | O34: Profiling Questionnaire | Q34: S1 | R34: 1. Trong 6 tháng vừa qua, BS đã được tiếp cận hoặc nhận thông tin từ công ty qua những hình thức/ kênh nào? | S34: S1_03 | T34: Hội thảo trực tuyến/ Gọi Video | V34: 2 | AB34: 46104.716
A35: ALLIANCE 1 | B35: VN20001294MSS000005 | C35: P | D35: 20001294 | E35: Nguyen Ngoc Diem | F35: 2026032300034782 | G35: 46104 | H35: 121050614 | I35: CONG TY TNHH BENH VIENDA KHOA HOAN HAO | J35: VN00063626 | K35: NGUYEN THI THUY TRANG | L35: OB_MSS_02 | M35: HCP Data Profiling Questionnaire | N35: Part_1 | O35: Profiling Questionnaire | Q35: S2 | R35: 2. Vui lòng đánh giá từng kênh theo thang điểm từ 0 đến 10, cho hình thức Gặp mặt trực tiếp/ Hội thảo đào tạo y khoa trực tiếp | S35: S2_05 | T35: 5 | V35: 2 | AB35: 46104.716
A36: ALLIANCE 1 | B36: VN20001294MSS000005 | C36: P | D36: 20001294 | E36: Nguyen Ngoc Diem | F36: 2026032300034782 | G36: 46104 | H36: 121050614 | I36: CONG TY TNHH BENH VIENDA KHOA HOAN HAO | J36: VN00063626 | K36: NGUYEN THI THUY TRANG | L36: OB_MSS_02 | M36: HCP Data Profiling Questionnaire | N36: Part_1 | O36: Profiling Questionnaire | Q36: S3 | R36: 2. Vui lòng đánh giá từng kênh theo thang điểm từ 0 đến 10, cho hình thức Email/ Mạng xã hội/ Tin nhắn | S36: S3_04 | T36: 4 | V36: 2 | AB36: 46104.716
A37: ALLIANCE 1 | B37: VN20001294MSS000005 | C37: P | D37: 20001294 | E37: Nguyen Ngoc Diem | F37: 2026032300034782 | G37: 46104 | H37: 121050614 | I37: CONG TY TNHH BENH VIENDA KHOA HOAN HAO | J37: VN00063626 | K37: NGUYEN THI THUY TRANG | L37: OB_MSS_02 | M37: HCP Data Profiling Questionnaire | N37: Part_1 | O37: Profiling Questionnaire | Q37: S4 | R37: 2. Vui lòng đánh giá từng kênh theo thang điểm từ 0 đến 10, cho hình thức Video call/ Hội thảo trực tuyến | S37: S4_03 | T37: 3 | V37: 2 | AB37: 46104.716
A38: ALLIANCE 1 | B38: VN20001294MSS000005 | C38: P | D38: 20001294 | E38: Nguyen Ngoc Diem | F38: 2026032300034782 | G38: 46104 | H38: 121050614 | I38: CONG TY TNHH BENH VIENDA KHOA HOAN HAO | J38: VN00063626 | K38: NGUYEN THI THUY TRANG | L38: OB_MSS_02 | M38: HCP Data Profiling Questionnaire | N38: Part_2 | O38: Digital / Personas Questionnaire | Q38: S1 | R38: 3. Ngoài các hình thức tiếp cận như gặp mặt trực tiếp/ tương tác trực tuyến hay thông qua các mạng xã hội…,còn nguồn thông tin nào khác mà BS thấy hữu ích cho việc cập nhật y khoa (ví dụ: hiệp hội, trang web hội chuyên ngành,...)? | U38: web | V38: 2 | AB38: 46104.716
A39: ALLIANCE 1 | B39: VN20001294MSS000005 | C39: P | D39: 20001294 | E39: Nguyen Ngoc Diem | F39: 2026032300034782 | G39: 46104 | H39: 121050614 | I39: CONG TY TNHH BENH VIENDA KHOA HOAN HAO | J39: VN00063626 | K39: NGUYEN THI THUY TRANG | L39: OB_MSS_02 | M39: HCP Data Profiling Questionnaire | N39: Part_2 | O39: Digital / Personas Questionnaire | Q39: S2 | R39: 4. BS thường ưu tiên tương tác với công ty theo hình thức nào? | S39: S2_03 | T39: Ưu tiên tương tác đa kênh | V39: 2 | AB39: 46104.716
A40: ALLIANCE 1 | B40: VN20001294MSS000005 | C40: P | D40: 20001294 | E40: Nguyen Ngoc Diem | F40: 2026032300034782 | G40: 46104 | H40: 121050614 | I40: CONG TY TNHH BENH VIENDA KHOA HOAN HAO | J40: VN00063626 | K40: NGUYEN THI THUY TRANG | L40: OB_MSS_02 | M40: HCP Data Profiling Questionnaire | N40: Part_2 | O40: Digital / Personas Questionnaire | Q40: S3 | R40: 5. Trong các yếu tố sau, yếu tố nào ảnh hưởng nhiều nhất đến quyết định điều trị của bác sĩ? | S40: S3_02 | T40: Dựa trên dữ liệu, bằng chứng khoa học (BLUE) | V40: 2 | AB40: 46104.716
...

Sheet Sheet1
A1: Question (Vietnamese)
A2: Trong 6 tháng vừa qua, BS đã được tiếp cận hoặc nhận thông tin từ công ty qua những hình thức/ kênh nào? 1. Gặp mặt trực tiếp/ Hội nghị đào tạo y khoa trực tiếp. 2. Email/ Mạng xã hội/ Tin nhắn. 3. Hội thảo trực tuyến/ Gọi Video
A3: Hoạt động nào được BS đánh giá cao nhất? Vui lòng đánh giá từng kênh theo thang điểm từ 0 đến 10, với 10 là giá trị cao nhất.
A4: Ngoài các hình thức tiếp cận trên, còn hình thức tiếp cận hay nguồn thông tin nào khác mà BS thấy hữu ích cho việc cập nhật y khoa (ví dụ: hiệp hội, trang web hội chuyên ngành, tạp chí ...)?
A5: BS thường ưu tiên tương tác với công ty theo hình thức nào? 1. Ưu tiên tương tác trực tiếp - 2. Kết hợp trực tiếp và kỹ thuật số - 3. Ưu tiên tương tác đa kênh
A6: Trong các yếu tố sau, yếu tố nào ảnh hưởng nhiều nhất đến quyết định điều trị của bác sĩ : Kết quả điều trị, Dữ liệu khoa học, Tác động đến bệnh nhân, hay Ảnh hưởng từ đồng nghiệp? 1. Kết quả điều trị thực tế (RED) - 2. Dựa trên dữ liệu, bằng chứng khoa học (BLUE), 3.Trải nghiệm và lợi ích tổng thể cho bệnh nhân (GREEN), 4. Ảnh hưởng bởi cộng đồng chuyên môn (YELLOW)

Sheet Sheet2
A1: cont_code | B1: Check
A2: HCP0000588 | B2: =_xlfn.XLOOKUP(A2,Market_Survey!J:J,Market_Survey!J:J) -> #N/A
A3: HCP0000604 | B3: =_xlfn.XLOOKUP(A3,Market_Survey!J:J,Market_Survey!J:J) -> #N/A
A4: HCP0000612 | B4: =_xlfn.XLOOKUP(A4,Market_Survey!J:J,Market_Survey!J:J) -> #N/A
A5: HCP0000634 | B5: =_xlfn.XLOOKUP(A5,Market_Survey!J:J,Market_Survey!J:J) -> #N/A
A6: HCP0000635 | B6: =_xlfn.XLOOKUP(A6,Market_Survey!J:J,Market_Survey!J:J) -> #N/A
A7: HCP0000636 | B7: =_xlfn.XLOOKUP(A7,Market_Survey!J:J,Market_Survey!J:J) -> #N/A
A8: HCP0000637 | B8: =_xlfn.XLOOKUP(A8,Market_Survey!J:J,Market_Survey!J:J) -> #N/A
A9: HCP0000638 | B9: =_xlfn.XLOOKUP(A9,Market_Survey!J:J,Market_Survey!J:J) -> #N/A
A10: HCP0000755 | B10: =_xlfn.XLOOKUP(A10,Market_Survey!J:J,Market_Survey!J:J) -> #N/A
A11: HCP0000756 | B11: =_xlfn.XLOOKUP(A11,Market_Survey!J:J,Market_Survey!J:J) -> #N/A
A12: HCP0000757 | B12: =_xlfn.XLOOKUP(A12,Market_Survey!J:J,Market_Survey!J:J) -> #N/A
A13: HCP0000758 | B13: =_xlfn.XLOOKUP(A13,Market_Survey!J:J,Market_Survey!J:J) -> #N/A
... A20597: VN00057739 | B20597: =_xlfn.XLOOKUP(A20597,Market_Survey!J:J,Market_Survey!J:J) -> VN00057739
